<?xml version="1.0"?>
<robot name="two_wheeler_robot">

    <!-- Base Chassis -->
    <link name="chassis">
        <visual>
            <geometry>
                <box size="0.4 0.3 0.1"/>
            </geometry>
            <material name="blue">
                <color rgba="0 0 1 1"/>
            </material>
        </visual>
        <collision>
            <geometry>
                <box size="0.4 0.3 0.1"/>
            </geometry>
        </collision>
        <inertial>
            <mass value="5"/>
            <inertia ixx="0.1" ixy="0" ixz="0" iyy="0.1" iyz="0" izz="0.1"/>
        </inertial>
    </link>

    <!-- Left Wheel -->
    <link name="left_wheel">
        <visual>
            <geometry>
                <cylinder length="0.05" radius="0.07"/>
            </geometry>
            <origin xyz="0 0 0" rpy="1.5708 0 0"/>
            <material name="black">
                <color rgba="0 0 0 1"/>
            </material>
        </visual>
        <collision>
            <geometry>
                <cylinder length="0.05" radius="0.07"/>
            </geometry>
            <origin xyz="0 0 0" rpy="1.5708 0 0"/>
        </collision>
        <inertial>
            <mass value="1"/>
            <inertia ixx="0.01" ixy="0" ixz="0" iyy="0.01" iyz="0" izz="0.01"/>
        </inertial>
    </link>

    <!-- Right Wheel -->
    <link name="right_wheel">
        <visual>
            <geometry>
                <cylinder length="0.05" radius="0.07"/>
            </geometry>
            <origin xyz="0 0 0" rpy="1.5708 0 0"/>
            <material name="black">
                <color rgba="0 0 0 1"/>
            </material>
        </visual>
        <collision>
            <geometry>
                <cylinder length="0.05" radius="0.07"/>
            </geometry>
            <origin xyz="0 0 0" rpy="1.5708 0 0"/>
        </collision>
        <inertial>
            <mass value="1"/>
            <inertia ixx="0.01" ixy="0" ixz="0" iyy="0.01" iyz="0" izz="0.01"/>
        </inertial>
    </link>

    <!-- LIDAR -->
    <link name="lidar_link">
        <visual>
            <geometry>
                <cylinder radius="0.05" length="0.02"/>
            </geometry>
            <material name="grey">
                <color rgba="0.5 0.5 0.5 1"/>
            </material>
        </visual>
    </link>

    <!-- Left Wheel Joint -->
    <joint name="left_wheel_joint" type="revolute">
        <parent link="chassis"/>
        <child link="left_wheel"/>
        <origin xyz="0 0.15 -0.05" rpy="0 0 0"/>
        <axis xyz="0 1 0"/>
        <limit lower="-100" upper="100" effort="10" velocity="10"/>
    </joint>

    <!-- Right Wheel Joint -->
    <joint name="right_wheel_joint" type="revolute">
        <parent link="chassis"/>
        <child link="right_wheel"/>
        <origin xyz="0 -0.15 -0.05" rpy="0 0 0"/>
        <axis xyz="0 1 0"/>
        <limit lower="-100" upper="100" effort="10" velocity="10"/>
    </joint>

    <!-- LIDAR Joint -->
    <joint name="lidar_joint" type="fixed">
        <parent link="chassis"/>
        <child link="lidar_link"/>
        <origin xyz="0 0 0.1" rpy="0 0 0"/>
    </joint>

    <!-- Gazebo Plugins -->
    <gazebo>
        <!-- Differential Drive Plugin -->
        <plugin name="diff_drive" filename="libgazebo_ros_diff_drive.so">
            <ros>
                <namespace>/</namespace>
                <remapping>cmd_vel:=/cmd_vel</remapping>
                <remapping>odom:=/odom</remapping>
            </ros>
            <update_rate>30</update_rate>
            <left_joint>left_wheel_joint</left_joint>
            <right_joint>right_wheel_joint</right_joint>
            <wheel_separation>0.3</wheel_separation>
            <wheel_radius>0.14</wheel_radius>
            <odom_frame>odom</odom_frame>
            <base_frame>chassis</base_frame>
            <publish_odom>true</publish_odom>
            <publish_tf>true</publish_tf>
        </plugin>
    </gazebo>

    <!-- LIDAR Plugin -->
    <gazebo reference="lidar_link">
        <sensor type="ray" name="lidar">
            <update_rate>10</update_rate>
            <ray>
                <scan>
                    <horizontal>
                        <samples>360</samples>
                        <resolution>1</resolution>
                        <min_angle>-3.14159</min_angle>
                        <max_angle>3.14159</max_angle>
                    </horizontal>
                </scan>
                <range>
                    <min>0.12</min>
                    <max>10.0</max>
                    <resolution>0.01</resolution>
                </range>
            </ray>
            <plugin name="gazebo_ros_laser" filename="libgazebo_ros_ray_sensor.so">
                <ros>
                    <namespace>/</namespace>
                    <remapping>scan:=/scan</remapping>
                </ros>
                <output_type>sensor_msgs/LaserScan</output_type>
            </plugin>
        </sensor>
    </gazebo>

</robot>